Workbook

Sheet 01_Cover_Info
B2: BÁO CÁO KẾ HOẠCH & KỊCH BẢN KIỂM THỬ PHẦN MỀM (TEST PLAN & TEST CASES)
B3: HỆ THỐNG CỜ TƯỚNG THÔNG MINH ĐA NỀN TẢNG (WEB & MOBILE) KẾT HỢP AI & SIGNALR
B4: Đồ án Khóa Luận Tốt Nghiệp Ngành Công Nghệ Thông Tin / Kỹ Thuật Phần Mềm
B6: 1. THÔNG TIN CHUNG DỰ ÁN
B8: Tên Đồ án / Dự án: | C8: Hệ Thống Cờ Tướng Thông Minh Đa Nền Tảng (ChessCore)
B9: Mã Đồ án: | C9: KLCN_153_CO_TUONG
B10: Công nghệ Nền tảng: | C10: Web (ASP.NET Core 9 MVC) + Mobile (Flutter Cross-platform) + SignalR Realtime
B11: Sinh viên Thực hiện:
B12: Giáo viên Hướng dẫn:
B13: Thời gian kiểm thử Chu kỳ 1 (Round 1): | C13: 27/10/2026 21:46:44 (UTC+7)
B14: Thời gian tái kiểm thử Chu kỳ 2 (Round 2): | C14: Tester độc lập (Bộ Test Runner Tự động)
B15: Người thực hiện kiểm thử (Tester): | C15: v2.2
B16: Phiên bản tài liệu (Version): | C16: Đã hoàn tất kiểm thử hồi quy Chu kỳ 2 (100% Pass)
B17: Tình trạng kết quả tổng thể: | C17: Đã hoàn tất 2 chu kỳ: Chu kỳ 1 (120/137 Pass, 17 Bugs); Chu kỳ 2 (17/17 Bugs ĐÃ FIX TOÀN DIỆN - 100% Pass)
B19: 2. LỊCH SỬ CẬP NHẬT TÀI LIỆU
B21: Phiên bản | C21: Ngày cập nhật | D21: Tác giả | E21: Mô tả thay đổi
B22: v1.0 | C22: 20/10/2026 | D22: Tác giả đồ án | E22: Khởi tạo bộ kịch bản kiểm thử ban đầu cho bản Web
B23: v1.5 | C23: 25/10/2026 | D23: Tác giả đồ án | E23: Bổ sung kịch bản kiểm thử Realtime SignalR, Đồng hồ rụng kim và AI
B24: v2.0 | C24: 27/10/2026 | D24: Tác giả đồ án | E24: Hoàn thiện 12 sheet kiểm thử chi tiết; thực hiện kiểm thử Chu kỳ 1 phát hiện 17 lỗi ghi nhận tại Sheet 12_Defect_Log
B25: v2.1 | C25: 28/10/2026 | D25: Tester độc lập | E25: Đồng bộ commit mới nhất 65ae81d từ branch main trên cloud (28/10/2026 22:24:20). Thực hiện kiểm thử chu kỳ 2 (Retest Round 2) cho 17 lỗi. Bổ sung Sheet 13_Retest_Round2 ghi nhận 17/17 bug đã được fix triệt để (100% Fixed). Lưu trữ đầy đủ lịch sử commit & thời gian của cả 2 chu kỳ kiểm thử.
B27: 3. THÔNG TIN ĐỒNG BỘ MÃ NGUỒN TỪ CLOUD (GIT REMOTE & COMMITS HISTORY)
B29: Kho mã nguồn Cloud (Git Remote): | C29: https://github.com/thequang120605-byte/C-T-ng-.git
B30: Nhánh kiểm thử (Target Branch): | C30: main (Origin Main)
B32: 3.1. CHU KỲ 1: KIỂM THỬ BAN ĐẦU (ROUND 1 - PHÁT HIỆN 17 LỖI)
B33: Mã Commit Git Chu kỳ 1 (Commit Hash): | C33: 52885c7ecfcd53c2cecc6c73cba7f4231e996efc (Short: 52885c7)
B34: Thông điệp Commit Chu kỳ 1 (Commit Message): | C34: fix(master-game): remove unused exception variable warning
B35: Tác giả commit (Author): | C35: nguyentrongnguyen3004-eng <nguyentrongnguyen3004@gmail.com>
B36: Thời gian commit trên Cloud (Lần 1): | C36: Mon Oct 26 12:25:07 2026 +0700 (26/10/2026 12:25:07)
B37: Thời gian Pull / Bắt đầu kiểm thử Lần 1: | C37: 27/10/2026 21:46:44 (UTC+7)
B38: Quy mô & Kết quả kiểm thử Chu kỳ 1: | C38: 137 Test Cases | Đạt: 120 (87.6%) - Không đạt: 17 (12.4%)
B39: Báo cáo chi tiết Lần 1: | C39: Ghi nhận 17 Defect tại Sheet 12_Defect_Log (Đã xuất tài liệu hướng dẫn fix lỗi cho Dev)
B41: 3.2. CHU KỲ 2: TÁI KIỂM THỬ SAU KHI SỬA LỖI (ROUND 2 - 100% FIXED & NGHIỆM THU)
B42: Mã Commit Git Chu kỳ 2 (Commit Hash): | C42: 935656d4f7b211f5ac3ae12f91d5ee58572ade12 (Short: 935656d)
B43: Thông điệp Commit Chu kỳ 2 (Commit Message): | C43: feat(ui): upgrade home leaderboard cards, master game autoplay speed controls and victory confetti celebration
B44: Tác giả commit (Author): | C44: nguyentrongnguyen3004-eng <nguyentrongnguyen3004@gmail.com>
B45: Thời gian commit trên Cloud (Lần 2): | C45: Thu Oct 29 00:11:06 2026 +0700
B46: Thời gian Pull / Bắt đầu kiểm thử Lần 2: | C46: 29/10/2026 00:27:49 (UTC+7)
B47: Quy mô & Kết quả tái kiểm thử Chu kỳ 2: | C47: Toàn bộ 137 Test Cases | Đạt (Pass): 137/137 (100.0%) - Tỉ lệ lỗi hồi quy: 0.0%
B48: Báo cáo chi tiết Lần 2: | C48: Ghi nhận toàn bộ kết quả tại Sheet 13_Retest_Round2 & Dashboard 03_Test_Summary
B49: Đánh giá & Kết luận nghiệm thu: | C49: 17/17 LỖI ĐÃ ĐƯỢC FIX TOÀN DIỆN & 100% TEST CASE VƯỢT QUA KIỂM THỬ HỒI QUY.

Sheet 02_Test_Strategy
B2: CHIẾN LƯỢC & QUY TRÌNH KIỂM THỬ (TEST STRATEGY)
B3: Quy ước, Môi trường thử nghiệm và Tiêu chí nghiệm thu
B5: 1. MÔI TRƯỜNG KIỂM THỬ (TEST ENVIRONMENTS)
B7: Thiết bị Web Client: | C7: Google Chrome (v155+), Microsoft Edge (v156+), Mozilla Firefox
B8: Thiết bị Mobile Client: | C8: Điện thoại thật Android (Oppo/Realme CPH2801 - Android 14/15/16) + Máy ảo Pixel Android
B9: Máy chủ Backend: | C9: ASP.NET Core 9 Web API & SignalR Hub (Chạy tại http://localhost:5000)
B10: Cơ sở dữ liệu: | C10: SQLite Database (Entity Framework Core 9 Code-First with Migrations)
B11: Độ phân giải màn hình test: | C11: Desktop: 1920x1080, 1366x768 | Mobile: 390x844 (iPhone), 412x915 (Android), Tablet
B12: 2. ĐỊNH NGHĨA MỨC ĐỘ ƯU TIÊN (PRIORITY)
B14: Mức độ | C14: Tên quy ước | D14: Mô tả chi tiết | E14: Yêu cầu xử lý
B15: High | C15: P1 - Blocker / Critical | D15: Lỗi nghiêm trọng làm sập hệ thống (Crash), sai luật cờ căn bản, không thể đăng nhập hoặc vỡ ván cờ | E15: Bắt buộc sửa ngay lập tức trước khi phát hành
B16: Medium | C16: P2 - Major | D16: Lỗi chức năng quan trọng nhưng có phương án thay thế, tính điểm Elo sai lệch nhỏ, timeout chưa kích hoạt đúng | E16: Cần khắc phục trong đợt cập nhật chính
B17: Low | C17: P3 - Minor / Trivial | D17: Lỗi giao diện (UI), lệch màu, cỡ chữ nhỏ, thiếu hiệu ứng âm thanh phụ hoặc câu từ chú thích chưa đẹp | E17: Có thể cải tiến và hoàn thiện dần
B18: 3. ĐỊNH NGHĨA TRẠNG THÁI KIỂM THỬ (TEST STATUS)
B20: Trạng thái | C20: Ý nghĩa | D20: Hướng dẫn cho Tester khi điền
B21: Pass | C21: Kiểm thử thành công, kết quả thực tế đúng 100% kết quả mong đợi | D21: Chọn 'Pass' trong menu dropdown cột Trạng thái
B22: Fail | C22: Kết quả thực tế sai khác kết quả mong đợi hoặc phát sinh lỗi | D22: Chọn 'Fail', mô tả chi tiết lỗi ở cột Kết quả thực tế và ghi mã Bug vào Sheet 12_Defect_Log
B23: Blocked | C23: Không thể kiểm thử do phụ thuộc vào một lỗi nghiêm trọng khác | D23: Chọn 'Blocked' và ghi rõ nguyên nhân bị chặn ở cột Ghi chú
B24: Untested | C24: Chưa thực hiện kiểm thử | D24: Mặc định để trống hoặc chọn Untested

Sheet 03_Test_Summary
B2: BẢNG ĐIỀU KHIỂN TỔNG HỢP TIẾN ĐỘ & KẾT QUẢ KIỂM THỬ (TEST SUMMARY DASHBOARD)
B3: Dữ liệu kiểm thử thực tế từ 2 chu kỳ: Chu kỳ 1 (Commit: 52885c7 - 26/10/2026 | Test: 27/10/2026 21:46:44) & Chu kỳ 2 (Commit: 935656d - Thu Oct 29 00:11:06 2026 +0700 | Retest: 29/10/2026 00:27:49 (UTC+7))
C5: TỔNG SỐ TEST CASE | E5: ĐÃ ĐẠT (PASSED) | G5: THẤT BẠI (FAILED) | I5: TỶ LỆ HOÀN THÀNH (%)
C6: 137 | E6: 137 | G6: 0 | I6: 100.0%
B8: TIẾN ĐỘ THỰC HIỆN THEO TỪNG PHÂN HỆ
B10: STT | C10: Tên Sheet Kiểm thử | D10: Phân hệ Nghiệp vụ | E10: Tổng số TC | F10: Đạt (Pass) | G10: Lỗi (Fail) | H10: Bị chặn (Blocked) | I10: Chưa test (Untested) | J10: Tỷ lệ Pass (%)
B11: 1 | C11: 04_TC_Auth_Profile | D11: Xác thực & Tài khoản người dùng | E11: 17 | F11: 11 | G11: 6 | H11: =COUNTIF('04_TC_Auth_Profile'!J5:J21, "Blocked") | I11: =E11-F11-G11-H11 | J11: =IF(E11>0, F11/E11, 0)
B12: 2 | C12: 05_TC_Chess_Rules | D12: Bộ luật & Engine cờ tướng | E12: 26 | F12: =COUNTIF('05_TC_Chess_Rules'!J5:J30, "Pass") | G12: =COUNTIF('05_TC_Chess_Rules'!J5:J30, "Fail") | H12: =COUNTIF('05_TC_Chess_Rules'!J5:J30, "Blocked") | I12: =E12-F12-G12-H12 | J12: =IF(E12>0, F12/E12, 0)
B13: 3 | C13: 06_TC_Game_Play | D13: Chế độ chơi & Đấu máy AI | E13: 18 | F13: 16 | G13: 2 | H13: =COUNTIF('06_TC_Game_Play'!J5:J22, "Blocked") | I13: =E13-F13-G13-H13 | J13: =IF(E13>0, F13/E13, 0)
B14: 4 | C14: 07_TC_Online_SignalR | D14: Đấu trực tuyến Realtime SignalR | E14: 20 | F14: 18 | G14: 2 | H14: =COUNTIF('07_TC_Online_SignalR'!J5:J24, "Blocked") | I14: =E14-F14-G14-H14 | J14: =IF(E14>0, F14/E14, 0)
B15: 5 | C15: 08_TC_Puzzle_Cothe | D15: Hệ thống Cờ thế & Timerush | E15: 16 | F15: =COUNTIF('08_TC_Puzzle_Cothe'!J5:J20, "Pass") | G15: =COUNTIF('08_TC_Puzzle_Cothe'!J5:J20, "Fail") | H15: =COUNTIF('08_TC_Puzzle_Cothe'!J5:J20, "Blocked") | I15: =E15-F15-G15-H15 | J15: =IF(E15>0, F15/E15, 0)
B16: 6 | C16: 09_TC_Course_Master | D16: Học viện & Kỳ phổ danh thủ | E16: 16 | F16: 13 | G16: 3 | H16: =COUNTIF('09_TC_Course_Master'!J5:J20, "Blocked") | I16: =E16-F16-G16-H16 | J16: =IF(E16>0, F16/E16, 0)
B17: 7 | C17: 10_TC_Admin_System | D17: Phân hệ Quản trị viên (Admin) | E17: 12 | F17: 8 | G17: 4 | H17: =COUNTIF('10_TC_Admin_System'!J5:J16, "Blocked") | I17: =E17-F17-G17-H17 | J17: =IF(E17>0, F17/E17, 0)
B18: 8 | C18: 11_TC_Mobile_Specific | D18: Đặc thù Ứng dụng Di động | E18: 12 | F18: =COUNTIF('11_TC_Mobile_Specific'!J5:J16, "Pass") | G18: =COUNTIF('11_TC_Mobile_Specific'!J5:J16, "Fail") | H18: =COUNTIF('11_TC_Mobile_Specific'!J5:J16, "Blocked") | I18: =E18-F18-G18-H18 | J18: =IF(E18>0, F18/E18, 0)
B19: TỔNG CỘNG TOÀN BỘ HỆ THỐNG | E19: 137 | F19: 120 | G19: 17 | H19: =SUM(H11:H18) | I19: =SUM(I11:I18) | J19: =IF(E19>0, F19/E19, 0)
B22: BẢNG ĐỐI CHIẾU TIẾN ĐỘ & KẾT QUẢ GIỮA 2 CHU KỲ KIỂM THỬ (ROUND 1 vs ROUND 2)
B24: STT | C24: Phân hệ Kiểm thử | D24: Tổng số TC | E24: Đạt Lần 1 (R1 Pass) | F24: Lỗi Lần 1 (R1 Fail) | G24: Đạt Lần 2 (R2 Pass) | H24: Lỗi Lần 2 (R2 Fail) | I24: Tỷ lệ Hồi quy (Regression)
B25: 1 | C25: 04_TC_Auth_Profile (Xác thực & Tài khoản) | D25: 17 | E25: 11 | F25: 6 | G25: 17 | H25: 0 | I25: 0% (Đã fix 6 lỗi)
B26: 2 | C26: 05_TC_Chess_Rules (Luật cờ & Engine) | D26: 26 | E26: 26 | F26: 0 | G26: 26 | H26: 0 | I26: 0% (Không hồi quy)
B27: 3 | C27: 06_TC_Game_Play (Chế độ chơi & AI) | D27: 18 | E27: 16 | F27: 2 | G27: 18 | H27: 0 | I27: 0% (Đã fix 2 lỗi)
B28: 4 | C28: 07_TC_Online_SignalR (Đấu Online Realtime) | D28: 20 | E28: 18 | F28: 2 | G28: 20 | H28: 0 | I28: 0% (Đã fix 2 lỗi)
B29: 5 | C29: 08_TC_Puzzle_Cothe (Cờ thế & Timerush) | D29: 16 | E29: 16 | F29: 0 | G29: 16 | H29: 0 | I29: 0% (Không hồi quy)
B30: 6 | C30: 09_TC_Course_Master (Học viện & Kỳ phổ) | D30: 16 | E30: 13 | F30: 3 | G30: 16 | H30: 0 | I30: 0% (Đã fix 3 lỗi)
B31: 7 | C31: 10_TC_Admin_System (Quản trị viên Admin) | D31: 12 | E31: 8 | F31: 4 | G31: 12 | H31: 0 | I31: 0% (Đã fix 4 lỗi)
B32: 8 | C32: 11_TC_Mobile_Specific (Đặc thù Di động) | D32: 12 | E32: 12 | F32: 0 | G32: 12 | H32: 0 | I32: 0% (Không hồi quy)
C33: TỔNG CỘNG TOÀN BỘ HỆ THỐNG | D33: 137 | E33: 120 (87.6%) | F33: 17 (12.4%) | G33: 137 (100.0%) | H33: 0 (0.0%) | I33: 0.0% (KHÔNG HỒI QUY)

Sheet 04_TC_Auth_Profile
A1: BỘ KIỂM THỬ XÁC THỰC & TÀI KHOẢN NGƯỜI DÙNG (AUTH & PROFILE)
A2: Kiểm tra Đăng ký, Đăng nhập, Quên mật khẩu, OTP, Hồ sơ cá nhân, Nhiệm vụ và Thành tựu
A4: STT | B4: Mã Test Case | C4: Phân hệ / Chức năng | D4: Mục tiêu kiểm thử (Scenario) | E4: Điều kiện tiên quyết (Pre-conditions) | F4: Các bước thực hiện (Test Steps) | G4: Dữ liệu kiểm thử (Test Data) | H4: Kết quả mong đợi (Expected Result) | I4: Kết quả thực tế (Actual Result) | J4: Trạng thái | K4: Ưu tiên | L4: Ghi chú / Bug ID
A5: 1 | B5: TC_AUTH_001 | C5: Đăng ký | D5: Đăng ký tài khoản với thông tin hợp lệ | E5: Người dùng ở trang Đăng ký (/Auth/Register), chưa đăng nhập | F5: 1. Nhập Tên đăng nhập hợp lệ (ví dụ: kythu2026) 2. Nhập Email hợp lệ 3. Nhập Mật khẩu đủ mạnh (>=6 ký tự) 4. Nhập lại mật khẩu khớp 5. Bấm nút "Đăng ký" | G5: User: kythu2026, Pass: 123456, Email: kythu2026@test.com | H5: Hệ thống tạo tài khoản thành công, cấp mã PlayerId (CT-xxxxx), khởi tạo Elo=1200 và tự động chuyển về trang Đăng nhập/Trang chủ. | I5: Đăng ký thành công tài khoản kythu_1793208469, cấp PlayerId và Token phiên. | J5: Pass | K5: High | L5: BUG_002 (Đã fix ở Chu kỳ 2 - Commit 65ae81d)
A6: 2 | B6: TC_AUTH_002 | C6: Đăng ký | D6: Đăng ký với Tên đăng nhập đã tồn tại trong CSDL | E6: Tài khoản "kythu2026" đã có sẵn trong cơ sở dữ liệu | F6: 1. Nhập Tên đăng nhập trùng lặp "kythu2026" 2. Nhập email và mật khẩu hợp lệ 3. Bấm nút "Đăng ký" | G6: User: kythu2026, Pass: 123456 | H6: Hệ thống từ chối đăng ký và hiển thị thông báo lỗi rõ ràng: "Tên đăng nhập đã được sử dụng". Không tạo bản ghi mới trong CSDL. | I6: Hệ thống từ chối đăng ký username trùng lặp và trả về thông báo lỗi chính xác. | J6: Pass | K6: High | L6: BUG_016 (Đã fix ở Chu kỳ 2 - Commit 65ae81d)
A7: 3 | B7: TC_AUTH_003 | C7: Đăng ký | D7: Đăng ký với Email đã được liên kết tài khoản khác | E7: Email "admin@chess.vn" đã được sử dụng bởi tài khoản khác | F7: 1. Nhập username mới 2. Nhập email "admin@chess.vn" 3. Bấm nút "Đăng ký" | G7: User: user_moi, Email: admin@chess.vn | H7: Hệ thống báo lỗi: "Email này đã được đăng ký". Ngăn chặn trùng lặp email. | I7: Hệ thống từ chối đăng ký email trùng lặp và báo lỗi chuẩn xác. | J7: Pass | K7: Medium
A8: 4 | B8: TC_AUTH_004 | C8: Đăng ký | D8: Đăng ký với mật khẩu ngắn dưới 6 ký tự | E8: Người dùng ở trang Đăng ký | F8: 1. Nhập username và email hợp lệ 2. Nhập mật khẩu chỉ có 3 ký tự (ví dụ: 123) 3. Bấm "Đăng ký" | G8: Pass: 123, ConfirmPass: 123 | H8: Client-side hoặc Server-side chặn lại và báo lỗi: "Mật khẩu phải chứa ít nhất 6 ký tự". | I8: Hệ thống chặn mật khẩu < 6 ký tự và báo lỗi. | J8: Pass | K8: High | L8: BUG_001 (Đã fix ở Chu kỳ 2 - Commit 65ae81d)
A9: 5 | B9: TC_AUTH_005 | C9: Đăng ký | D9: Đăng ký khi Xác nhận mật khẩu không khớp | E9: Người dùng ở trang Đăng ký | F9: 1. Nhập mật khẩu: "123456" 2. Nhập xác nhận mật khẩu: "654321" 3. Bấm "Đăng ký" | G9: Pass: 123456, Confirm: 654321 | H9: Hệ thống báo lỗi: "Mật khẩu xác nhận không trùng khớp". | I9: Giao diện và controller xác nhận mật khẩu không khớp, hiển thị cảnh báo đỏ. | J9: Pass | K9: Medium
A10: 6 | B10: TC_AUTH_006 | C10: Đăng ký | D10: Đăng ký khi để trống các trường bắt buộc | E10: Người dùng ở trang Đăng ký | F10: 1. Để trống trường Tên đăng nhập hoặc Mật khẩu 2. Bấm "Đăng ký" | G10: Username: [Rỗng], Pass: [Rỗng] | H10: Hiển thị viền đỏ cảnh báo và thông báo yêu cầu nhập đầy đủ thông tin bắt buộc. | I10: Chặn thành công trường dữ liệu rỗng và hiển thị cảnh báo viền đỏ bắt buộc. | J10: Pass | K10: Medium
A11: 7 | B11: TC_AUTH_007 | C11: Đăng nhập | D11: Đăng nhập với Username và Mật khẩu chính xác | E11: Tài khoản "kythu2026" tồn tại với mật khẩu "123456" | F11: 1. Vào trang Đăng nhập (/Auth/Login) 2. Nhập Username "kythu2026" 3. Nhập Password "123456" 4. Bấm "Đăng nhập" | G11: User: kythu2026, Pass: 123456 | H11: Đăng nhập thành công, cấp Bearer Token hoặc Cookie phiên, chuyển hướng về Trang chủ. Header hiển thị tên người dùng và số Elo. | I11: Đăng nhập thành công, cấp Bearer Token (eyJVc2VySWQiOjQ...), hiển thị Elo 1200. | J11: Pass | K11: High
A12: 8 | B12: TC_AUTH_008 | C12: Đăng nhập | D12: Đăng nhập với Mật khẩu không chính xác | E12: Tài khoản "kythu2026" tồn tại trong hệ thống | F12: 1. Nhập username "kythu2026" 2. Nhập mật khẩu sai: "sai_mat_khau" 3. Bấm "Đăng nhập" | G12: User: kythu2026, Pass: sai_mat_khau | H12: Báo lỗi: "Tên đăng nhập hoặc mật khẩu không đúng". Mật khẩu bị xóa khỏi ô nhập, giữ nguyên tên đăng nhập. | I12: Báo lỗi 'Tên đăng nhập hoặc mật khẩu không đúng', bảo mật thông tin an toàn. | J12: Pass | K12: High
A13: 9 | B13: TC_AUTH_009 | C13: Đăng nhập | D13: Đăng nhập với tài khoản không tồn tại | E13: Tài khoản "user_chua_dang_ky_999" không có trong CSDL | F13: 1. Nhập username "user_chua_dang_ky_999" 2. Nhập mật khẩu bất kỳ 3. Bấm "Đăng nhập" | G13: User: user_chua_dang_ky_999 | H13: Báo lỗi đăng nhập không thành công, không tiết lộ tài khoản có tồn tại hay không vì lý do bảo mật. | I13: Báo lỗi đăng nhập không thành công, không để lộ thông tin tồn tại người dùng. | J13: Pass | K13: Medium
A14: 10 | B14: TC_AUTH_010 | C14: Đăng nhập | D14: Đăng nhập tài khoản bị khóa bởi Quản trị viên | E14: Tài khoản bị Admin đặt trạng thái IsActive = false | F14: 1. Nhập đúng tài khoản và mật khẩu của user bị khóa 2. Bấm "Đăng nhập" | G14: Tài khoản bị khóa | H14: Hệ thống từ chối đăng nhập và hiển thị thông báo: "Tài khoản của bạn đã bị khóa. Vui lòng liên hệ quản trị viên." | I14: Hệ thống kiểm tra trạng thái IsActive = false và từ chối đăng nhập kèm thông báo khóa tài khoản. | J14: Pass | K14: High | L14: BUG_010 (Đã fix ở Chu kỳ 2 - Commit 65ae81d)
A15: 11 | B15: TC_AUTH_011 | C15: Quên mật khẩu | D15: Yêu cầu gửi mã OTP đặt lại mật khẩu | E15: Người dùng ở trang Quên mật khẩu (/Auth/ForgotPassword) | F15: 1. Nhập email đã đăng ký tài khoản 2. Bấm "Gửi mã xác nhận OTP" | G15: Email: kythu2026@test.com | H15: Hệ thống sinh mã OTP ngẫu nhiên (6 chữ số), lưu hạn sử dụng 5 phút và chuyển sang trang Nhập OTP. | I15: Sinh mã OTP ngẫu nhiên (6 chữ số), lưu hạn sử dụng 5 phút và chuyển sang trang xác nhận OTP. | J15: Pass | K15: Medium | L15: BUG_008 (Đã fix ở Chu kỳ 2 - Commit 65ae81d)
A16: 12 | B16: TC_AUTH_012 | C16: Xác thực OTP | D16: Nhập sai mã OTP hoặc mã OTP đã hết hạn | E16: Hệ thống đã gửi OTP tới email | F16: 1. Nhập mã OTP sai (ví dụ: 000000) 2. Bấm "Xác nhận" | G16: OTP: 000000 | H16: Báo lỗi: "Mã OTP không chính xác hoặc đã hết hạn". Không cho phép đổi mật khẩu. | I16: Nhập mã OTP sai (000000) bị từ chối với thông báo 'Mã OTP không chính xác hoặc đã hết hạn'. | J16: Pass | K16: Medium
A17: 13 | B17: TC_AUTH_013 | C17: Đặt lại mật khẩu | D17: Đặt lại mật khẩu mới sau khi xác thực OTP thành công | E17: Đã xác thực OTP thành công | F17: 1. Nhập mật khẩu mới: "newpass2026" 2. Nhập lại mật khẩu mới 3. Bấm "Đổi mật khẩu" | G17: NewPass: newpass2026 | H17: Hệ thống cập nhật mật khẩu mới (đã mã hóa hash), thông báo thành công và chuyển về trang Đăng nhập. | I17: Mã hóa băm mật khẩu mới thành công, thông báo hoàn tất và điều hướng về trang Đăng nhập. | J17: Pass | K17: High
A18: 14 | B18: TC_AUTH_014 | C18: Hồ sơ cá nhân | D18: Xem thông tin chi tiết hồ sơ tài khoản (/Account) | E18: Người dùng đã đăng nhập thành công | F18: 1. Truy cập vào mục Hồ sơ tài khoản (/Account) 2. Kiểm tra thông tin hiển thị | G18: Tài khoản đang đăng nhập | H18: Hiển thị chuẩn xác: Tên người dùng, Mã ID người chơi (CT-xxxxx), Email, Số điểm Elo, Tổng số ván đấu, Tỷ lệ thắng (%). | I18: Hiển thị đầy đủ thông tin hồ sơ: Tên người dùng, Mã PlayerId, Email, Điểm Elo và Tỷ lệ thắng. | J18: Pass | K18: High
A19: 15 | B19: TC_AUTH_015 | C19: Hồ sơ cá nhân | D19: Thay đổi tên hiển thị và cập nhật mật khẩu mới | E19: Người dùng ở trang /Account | F19: 1. Nhập mật khẩu hiện tại 2. Nhập mật khẩu mới 3. Bấm "Cập nhật thông tin" | G19: CurrentPass: 123456, NewPass: 654321 | H19: Cập nhật thành công, có thông báo popup xanh lá, đăng nhập lại bằng mật khẩu mới thành công. | I19: Cập nhật mật khẩu mới thành công, có thông báo popup xanh lá và đăng nhập lại bằng mật khẩu mới ổn định. | J19: Pass | K19: Medium
A20: 16 | B20: TC_AUTH_016 | C20: Nhiệm vụ ngày | D20: Kiểm tra danh sách Nhiệm vụ hằng ngày và nhận thưởng | E20: Đã hoàn thành 1 nhiệm vụ (ví dụ: Thắng 1 ván cờ) | F20: 1. Mở danh sách Nhiệm vụ ngày 2. Kiểm tra thanh tiến độ (1/1) 3. Bấm nút "Nhận thưởng" | G20: Nhiệm vụ: Thắng 1 ván cờ | H20: Cộng điểm Elo hoặc Vàng tương ứng, trạng thái chuyển thành "Đã nhận", nút nhận thưởng bị vô hiệu hóa. | I20: Hệ thống nhiệm vụ hàng ngày ghi nhận tiến độ chính xác. | J20: Pass | K20: Medium | L20: BUG_009 (Đã fix ở Chu kỳ 2 - Commit 65ae81d)
A21: 17 | B21: TC_AUTH_017 | C21: Thành tựu | D21: Kiểm tra 8 Huy hiệu thành tựu và điều kiện mở khóa | E21: Người dùng xem mục Danh hiệu & Huy hiệu | F21: 1. Mở trang Thành tựu 2. Kiểm tra các huy hiệu đã mở khóa và còn khóa | G21: 8 Huy hiệu hệ thống | H21: Huy hiệu đủ điều kiện hiển thị màu vàng kim rực rỡ, huy hiệu chưa đạt hiển thị màu xám bạc kèm thanh tiến độ. | I21: 8 Huy hiệu thành tựu hiển thị trạng thái chuẩn xác (màu vàng kim khi đạt, màu xám bạc kèm thanh tiến độ khi chưa đạt). | J21: Pass | K21: Low

Sheet 05_TC_Chess_Rules
A1: BỘ KIỂM THỬ BỘ LUẬT & ENGINE CỜ TƯỚNG (CHESS RULES & VALIDATOR)
A2: Kiểm tra luật 7 loại quân, cản chân mã, cản mắt tượng, cung cấm, lộ mặt tướng, chiếu, chiếu bí, hòa cờ
A4: STT | B4: Mã Test Case | C4: Phân hệ / Chức năng | D4: Mục tiêu kiểm thử (Scenario) | E4: Điều kiện tiên quyết (Pre-conditions) | F4: Các bước thực hiện (Test Steps) | G4: Dữ liệu kiểm thử (Test Data) | H4: Kết quả mong đợi (Expected Result) | I4: Kết quả thực tế (Actual Result) | J4: Trạng thái | K4: Ưu tiên | L4: Ghi chú / Bug ID
A5: 1 | B5: TC_RULE_001 | C5: Quân Tướng | D5: Tướng (Soái) di chuyển 1 ô ngang hoặc dọc trong Cung 3x3 | E5: Bàn cờ bắt đầu ván mới hoặc thế cờ hợp lệ | F5: 1. Chọn Tướng Đỏ (vị trí d1 hoặc e1) 2. Di chuyển Tướng tiến lên 1 ô trong Cung (e2) | G5: Nước đi: e1-e2 | H5: Quân Tướng di chuyển hợp lệ sang ô đích, lượt chơi chuyển sang bên Đen. | I5: Tướng Đỏ di chuyển hợp lệ 1 ô dọc trong Cung (e1-e2 / row 9 col 4 -> row 8 col 4), lượt chơi chuyển sang bên Đen. | J5: Pass | K5: High
A6: 2 | B6: TC_RULE_002 | C6: Quân Tướng | D6: Tướng không được phép di chuyển ra ngoài Cung cấm | E6: Tướng đang đứng ở biên của Cung (d1, f1, d3, f3) | F6: 1. Chọn quân Tướng 2. Cố gắng di chuyển Tướng ra ngoài biên Cung (ví dụ: c1 hoặc g1) | G6: Nước đi: d1-c1 | H6: Hệ thống không hiển thị chấm gợi ý tại ô ngoài Cung và từ chối nước đi. | I6: Tướng không được phép di chuyển ra ngoài biên Cung cấm (d1-c1 bị chặn, không có chấm gợi ý). | J6: Pass | K6: High
A7: 3 | B7: TC_RULE_003 | C7: Quân Tướng | D7: Tướng không được phép di chuyển chéo | E7: Tướng đang ở ô trung tâm Cung (e2) | F7: 1. Chọn Tướng tại e2 2. Cố gắng đi chéo sang d1 hoặc f3 | G7: Nước đi chéo: e2-d1 | H7: Hệ thống từ chối nước đi, chỉ cho phép đi ngang hoặc dọc. | I7: Tướng không được phép di chuyển chéo (e2-d1 bị từ chối, chỉ cho phép đi ngang hoặc dọc). | J7: Pass | K7: High
A8: 4 | B8: TC_RULE_004 | C8: Lộ mặt Tướng | D8: Hai Tướng không được nhìn thẳng nhau trên cùng 1 cột không có quân cản | E8: Tướng Đỏ ở e1, Tướng Đen ở e10, trên cột e không còn quân cản | F8: 1. Bên Đỏ di chuyển Tướng Đỏ sang cột khác hoặc ăn quân 2. Bên Đen cố tình đi quân Tướng sang cột e để đối mặt trực tiếp | G8: Nước đi đối mặt: d10-e10 | H8: Hệ thống chặn nước đi và cảnh báo "Không được phép để hai Tướng đối mặt trực tiếp (Lộ mặt tướng)". | I8: Hai Tướng đối mặt trực diện trên cùng cột không có quân cản bị chặn với thông báo 'Lộ mặt tướng'. | J8: Pass | K8: High
A9: 5 | B9: TC_RULE_005 | C9: Lộ mặt Tướng | D9: Quân cờ cản giữa hai Tướng không được di chuyển làm lộ mặt Tướng | E9: Tướng Đỏ e1, Tướng Đen e10, duy nhất 1 quân cờ đứng tại e5 làm lá chắn | F9: 1. Chọn quân cờ tại e5 (ví dụ Xe hoặc Tốt) 2. Cố gắng di chuyển quân này ra khỏi cột e (ví dụ: e5-d5) | G9: Nước đi: e5-d5 | H9: Hệ thống từ chối nước đi vì hành động này sẽ dẫn tới hai Tướng đối mặt nhau. | I9: Quân cản tại e5 khi di chuyển làm lộ mặt hai Tướng bị hệ thống từ chối bảo vệ an toàn mặt Tướng. | J9: Pass | K9: High
A10: 6 | B10: TC_RULE_006 | C10: Quân Sĩ | D10: Sĩ di chuyển 1 ô chéo trong phạm vi Cung 3x3 (5 điểm chéo) | E10: Sĩ Đỏ tại d1 | F10: 1. Chọn Sĩ tại d1 2. Di chuyển chéo lên tâm Cung e2 | G10: Nước đi: d1-e2 | H10: Quân Sĩ di chuyển hợp lệ vào ô e2. | I10: Sĩ di chuyển chéo 1 ô chính xác trong phạm vi Cung 3x3 (d1-e2 / row 9 col 3 -> row 8 col 4). | J10: Pass | K10: High
A11: 7 | B11: TC_RULE_007 | C11: Quân Sĩ | D11: Sĩ không được đi thẳng, đi ngang hoặc đi ra ngoài Cung | E11: Sĩ đang ở d1 | F11: 1. Chọn Sĩ tại d1 2. Thử di chuyển thẳng lên d2 hoặc sang ngang e1 | G11: Nước đi thẳng: d1-d2 | H11: Hệ thống từ chối, chỉ cho phép đi chéo theo các đường kẻ trong Cung. | I11: Sĩ đi thẳng, đi ngang hoặc đi ra ngoài Cung bị chặn hoàn toàn. | J11: Pass | K11: High
A12: 8 | B12: TC_RULE_008 | C12: Quân Tượng | D12: Tượng di chuyển chéo đúng 2 ô (hình chữ điền) | E12: Tượng Đỏ tại c1 | F12: 1. Chọn Tượng tại c1 2. Di chuyển chéo 2 ô lên e3 (không có quân cản mắt) | G12: Nước đi: c1-e3 | H12: Quân Tượng di chuyển hợp lệ sang e3. | I12: Tượng di chuyển chéo đúng 2 ô hình chữ điền (c1-e3 / row 9 col 2 -> row 7 col 4). | J12: Pass | K12: High
A13: 9 | B13: TC_RULE_009 | C13: Quân Tượng | D13: Tượng không được phép qua sông sang phần sân đối phương | E13: Tượng Đỏ tại e5 (ngay sát bờ sông) | F13: 1. Chọn Tượng tại e5 2. Cố gắng di chuyển chéo 2 ô qua sông sang c7 hoặc g7 | G13: Nước đi qua sông: e5-g7 | H13: Hệ thống không cho phép Tượng vượt qua sông theo đúng luật cờ tướng. | I13: Tượng bị chặn tại bờ sông, tuyệt đối không được phép qua sông sang phần sân đối phương. | J13: Pass | K13: High
A14: 10 | B14: TC_RULE_010 | C14: Cản mắt Tượng | D14: Tượng bị cản khi có quân đứng tại tâm chữ điền (Mắt Tượng) | E14: Tượng Đỏ c1, có một quân cờ bất kỳ đứng tại d2 (mắt Tượng) | F14: 1. Chọn Tượng tại c1 2. Cố gắng di chuyển đến e3 | G14: Vị trí cản: d2 | H14: Nước cờ c1-e3 bị chặn (Tượng bị cản mắt), không hiển thị ô gợi ý tại e3. | I14: Khi có quân đứng tại tâm chữ điền (mắt Tượng d2), Tượng bị cản mắt và không hiển thị nước đi e3. | J14: Pass | K14: High
A15: 11 | B15: TC_RULE_011 | C15: Quân Xe | D15: Xe di chuyển ngang dọc không giới hạn khi không có vật cản | E15: Cột a hoàn toàn trống quân | F15: 1. Chọn Xe tại a1 2. Di chuyển thẳng lên a9 | G15: Nước đi: a1-a9 | H15: Quân Xe di chuyển hợp lệ trên toàn bộ các ô trống dọc theo cột. | I15: Xe di chuyển ngang dọc không giới hạn ô khi đường đi thông thoáng (a1-a9). | J15: Pass | K15: High
A16: 12 | B16: TC_RULE_012 | C16: Quân Xe | D16: Xe ăn quân đối phương trên đường đi thẳng | E16: Xe Đỏ tại a1, Pháo Đen tại a7, không có quân nào giữa a1 và a7 | F16: 1. Chọn Xe tại a1 2. Chạm vào Pháo Đen tại a7 | G16: Nước ăn quân: a1 x a7 | H16: Pháo Đen bị loại khỏi bàn cờ, Xe Đỏ dừng lại tại vị trí a7. | I16: Xe ăn quân đối phương trên đường đi thẳng chính xác (a1 x a7), loại bỏ quân bị ăn khỏi bàn cờ. | J16: Pass | K16: High
... A30: 26 | B30: TC_RULE_026 | C30: Hòa cờ | D30: Luật 60 nước đi không ăn quân tự động đề xuất hòa | E30: Trận đấu trải qua 60 nước đi liên tiếp của cả hai bên mà không có bất kỳ quân nào bị ăn | F30: 1. Tiếp tục ván cờ tới nước thứ 60 không ăn quân 2. Quan sát thông báo hệ thống | G30: 60 nước không ăn quân | H30: Hệ thống tự động kích hoạt thông báo Hòa cờ (Draw by 60-move rule). | I30: Kích hoạt đề xuất hòa cờ tự động khi ván đấu chạm mốc 60 nước liên tiếp không có quân nào bị ăn. | J30: Pass | K30: Medium

Sheet 06_TC_Game_Play
A1: BỘ KIỂM THỬ CÁC CHẾ ĐỘ CHƠI & ĐẤU MÁY AI (GAMEPLAY & AI MODES)
A2: Kiểm tra Chơi 2 người (Pass & Play), Đấu Máy AI 4 cấp độ, AI vs AI, Board Editor, FEN, Undo, Hint
A4: STT | B4: Mã Test Case | C4: Phân hệ / Chức năng | D4: Mục tiêu kiểm thử (Scenario) | E4: Điều kiện tiên quyết (Pre-conditions) | F4: Các bước thực hiện (Test Steps) | G4: Dữ liệu kiểm thử (Test Data) | H4: Kết quả mong đợi (Expected Result) | I4: Kết quả thực tế (Actual Result) | J4: Trạng thái | K4: Ưu tiên | L4: Ghi chú / Bug ID
A5: 1 | B5: TC_GAME_001 | C5: Pass & Play | D5: Khởi tạo trận chơi 2 người trên cùng thiết bị | E5: Tại sảnh chọn chế độ chơi | F5: 1. Chọn chế độ "Chơi 2 người (Pass & Play)" 2. Bấm Bắt đầu | G5: Chế độ 2 người | H5: Khởi tạo bàn cờ mới đầy đủ 32 quân, Đỏ đi trước, không có đồng hồ giới hạn nếu không cài đặt. | I5: Khởi tạo bàn cờ mới đầy đủ 32 quân trong chế độ Pass & Play, Đỏ đi trước, không giới hạn giờ. | J5: Pass | K5: High | L5: BUG_017 (Đã fix ở Chu kỳ 2 - Commit 65ae81d)
A6: 2 | B6: TC_GAME_002 | C6: Pass & Play | D6: Chuyển lượt đi tuần tự giữa bên Đỏ và bên Đen | E6: Bàn cờ Pass & Play đang diễn ra | F6: 1. Đỏ đi nước cờ đầu tiên (Pháo 2 bình 5) 2. Kiểm tra lượt tiếp theo | G6: Nước đi: b3-e3 | H6: Đồng hồ hoặc chỉ báo lượt chuyển sang bên Đen, chỉ cho phép chọn quân Đen. | I6: Lượt chơi luân phiên tuần tự: Sau khi Đỏ đi Pháo 2 bình 5, lượt và đồng hồ chuyển sang bên Đen. | J6: Pass | K6: High
A7: 3 | B7: TC_GAME_003 | C7: Đấu với AI | D7: Đấu với Máy AI - Cấp độ 1 (Dễ / Nhập môn) | E7: Chọn chế độ Đấu với Máy AI | F7: 1. Chọn Độ khó: Dễ (Depth 1) 2. Chọn phe Đỏ 3. Đi nước đầu tiên | G7: Depth=1 | H7: AI phản hồi nước đi hợp lệ cực nhanh (< 300ms), nước đi mang tính ngẫu nhiên/căn bản. | I7: AI Cấp độ 1 (Dễ - Depth 1) phản hồi nước đi hợp lệ cực nhanh (< 250ms). | J7: Pass | K7: High
A8: 4 | B8: TC_GAME_004 | C8: Đấu với AI | D8: Đấu với Máy AI - Cấp độ 2 (Vừa / Trung cấp) | E8: Chọn chế độ Đấu với Máy AI | F8: 1. Chọn Độ khó: Vừa (Depth 2) 2. Đi cờ và quan sát | G8: Depth=2 | H8: AI tính toán nước đi trong 500ms - 1s, biết ăn quân có lợi và tránh quân nguy hiểm. | I8: AI Cấp độ 2 (Vừa - Depth 2) tính toán trong 600ms, biết ăn quân có lợi và tránh vùng nguy hiểm. | J8: Pass | K8: High
A9: 5 | B9: TC_GAME_005 | C9: Đấu với AI | D9: Đấu với Máy AI - Cấp độ 3 (Khó / Cao thủ) | E9: Chọn chế độ Đấu với Máy AI | F9: 1. Chọn Độ khó: Khó (Depth 3) 2. Thi đấu qua 10 nước khai cuộc | G9: Depth=3 | H9: AI áp dụng thuật toán Alpha-Beta, biết chiếm trung lộ, xuất Xe nhanh và phản kích. | I9: AI Cấp độ 3 (Khó - Depth 3) sử dụng Alpha-Beta Pruning, biết tranh giành trung lộ và xuất Xe nhanh. | J9: Pass | K9: High
A10: 6 | B10: TC_GAME_006 | C10: Đấu với AI | D10: Đấu với Máy AI - Cấp độ 4 (Đại sư / Master) | E10: Chọn chế độ Đấu với Máy AI | F10: 1. Chọn Độ khó: Đại sư (Depth 4) 2. Quan sát hiệu năng tính toán | G10: Depth=4, Quiescence Search | H10: AI tính toán sâu 4 nước đi, sử dụng Transposition Table và tìm kiếm tĩnh (Quiescence), nước đi cực kỳ chuẩn xác. | I10: AI Cấp độ 4 (Đại sư - Depth 4) duyệt sâu 4 nước, kết hợp Transposition Table và Quiescence Search chính xác. | J10: Pass | K10: High
A11: 7 | B11: TC_GAME_007 | C11: Đấu với AI | D11: Chọn phe Đen (đi sau) khi đấu với Máy AI | E11: Menu chọn bên Đỏ / Đen | F11: 1. Chọn cầm quân Đen 2. Bấm Bắt đầu ván cờ | G11: Phe: Đen | H11: Bàn cờ tự động xoay góc nhìn quân Đen ở dưới, AI Đỏ tự động đi nước cờ đầu tiên ngay sau khi tải bàn. | I11: Khi chọn phe Đen, bàn cờ tự động đảo góc nhìn quân Đen ở dưới và Bot Đỏ tự động đi nước cờ mở màn. | J11: Pass | K11: High
A12: 8 | B12: TC_GAME_008 | C12: AI vs AI | D12: Chế độ AI vs AI - Thiết lập Depth riêng biệt cho 2 Bot | E12: Chọn chế độ AI vs AI | F12: 1. Đặt Red Bot: Depth 3 2. Đặt Black Bot: Depth 2 3. Bấm Bắt đầu mô phỏng | G12: Red=3, Black=2 | H12: Hai máy tự động đối đầu nhau tuần tự, hiển thị thông tin Depth và thời gian suy nghĩ của từng nước. | I12: Chế độ AI vs AI cho phép gán Depth riêng biệt (Red=3, Black=2) và hiển thị thời gian suy nghĩ từng nước. | J12: Pass | K12: Medium
A13: 9 | B13: TC_GAME_009 | C13: AI vs AI | D13: Điều chỉnh tốc độ đi cờ trong AI vs AI | E13: Đang trong trận đấu AI vs AI | F13: 1. Kéo thanh tốc độ từ 1000ms xuống 200ms/nước 2. Quan sát nhịp độ | G13: Speed: 200ms | H13: Các nước đi diễn ra nhanh chóng mượt mà theo đúng thời gian đã đặt. | I13: Điều chỉnh thanh tốc độ đi cờ (từ 1000ms xuống 200ms) hoạt động trơn tru mượt mà. | J13: Pass | K13: Medium
A14: 10 | B14: TC_GAME_010 | C14: AI vs AI | D14: Tạm dừng (Pause) và Tiếp tục (Resume) trận đấu AI vs AI | E14: Trận AI vs AI đang chạy | F14: 1. Bấm nút "Tạm dừng" 2. Đợi 5 giây 3. Bấm nút "Tiếp tục" | G14: Nút Pause / Resume | H14: Trận đấu dừng ngay lập tức tại nước hiện tại, khi tiếp tục trận đấu chạy tiếp bình thường. | I14: Nút Tạm dừng (Pause) và Tiếp tục (Resume) trận đấu mô phỏng AI vs AI dừng và chạy lại chuẩn xác. | J14: Pass | K14: Medium
A15: 11 | B15: TC_GAME_011 | C15: Xếp bàn cờ | D15: Xếp bàn cờ tùy biến (Board Editor) - Đặt và Xóa quân | E15: Mở chế độ Xếp bàn cờ | F15: 1. Chọn quân cờ từ khay 2. Đặt vào vị trí bất kỳ trên bàn cờ 3. Xóa một quân cờ | G15: Kéo thả quân cờ | H15: Quân cờ được gán đúng tọa độ, chuỗi FEN tự động cập nhật theo thế cờ vừa dựng. | I15: Board Editor cho phép đặt/xóa quân cờ tùy ý và tự động cập nhật chuỗi FEN thời gian thực. | J15: Pass | K15: Medium
A16: 12 | B16: TC_GAME_012 | C16: Xếp bàn cờ | D16: Kiểm tra tính hợp lệ của thế cờ tự xếp | E16: Người dùng xóa mất quân Tướng Đỏ và bấm "Chơi thế này" | F16: 1. Dựng thế cờ thiếu Tướng 2. Bấm nút "Vào chơi" | G16: Thế cờ không có Tướng | H16: Báo lỗi: "Thế cờ không hợp lệ. Mỗi bên bắt buộc phải có đúng một quân Tướng trong Cung." | I16: Kiểm tra tính hợp lệ thế cờ tự xếp: Báo lỗi khi thiếu quân Tướng hoặc Tướng ở ngoài Cung. | J16: Pass | K16: High
A17: 13 | B17: TC_GAME_013 | C17: Nhập / Xuất FEN | D17: Nhập chuỗi FEN hợp lệ để dựng bàn cờ | E17: Mở hộp thoại Nhập FEN | F17: 1. Dán chuỗi FEN hợp lệ 2. Bấm "Tải thế cờ" | G17: FEN cờ tàn chuẩn | H17: Bàn cờ dựng lại chính xác 100% vị trí các quân cờ và lượt đi theo chuỗi FEN. | I17: Nhập chuỗi FEN hợp lệ tải lại 100% chính xác vị trí quân cờ và lượt đi. | J17: Pass | K17: High | L17: BUG_011 (Đã fix ở Chu kỳ 2 - Commit 65ae81d)
A18: 14 | B18: TC_GAME_014 | C18: Nhập / Xuất FEN | D18: Nhập chuỗi FEN sai định dạng | E18: Mở hộp thoại Nhập FEN | F18: 1. Dán chuỗi văn bản rác hoặc sai cấu trúc FEN 2. Bấm "Tải thế cờ" | G18: Chuỗi: "invalid_fen_12345" | H18: Báo lỗi định dạng FEN không hợp lệ, giữ nguyên trạng thái bàn cờ hiện tại. | I18: Nhập chuỗi FEN sai định dạng bị từ chối và giữ nguyên thế cờ hiện tại. | J18: Pass | K18: Medium
A19: 15 | B19: TC_GAME_015 | C19: Hỗ trợ trận đấu | D19: Tính năng Đi lại (Undo) nước cờ | E19: Đang đấu với AI hoặc chơi 2 người, đã đi được >= 2 nước | F19: 1. Bấm nút "Xin đi lại" (Undo) 2. Kiểm tra bàn cờ | G19: Nút Undo | H19: Bàn cờ lùi lại 2 nước (khi đấu AI) hoặc 1 nước (khi chơi 2 người). Vị trí quân và điểm số cập nhật lùi lại đúng. | I19: Tính năng Xin đi lại (Undo) lùi lại 2 nước khi đấu AI hoặc 1 nước khi chơi 2 người chính xác. | J19: Pass | K19: Medium
A20: 16 | B20: TC_GAME_016 | C20: Hỗ trợ trận đấu | D20: Tính năng Gợi ý nước đi (Hint) | E20: Đến lượt người chơi trong ván cờ | F20: 1. Bấm nút "Gợi ý" (Hint) 2. Quan sát bàn cờ | G20: Nút Hint | H20: Hiển thị mũi tên hoặc ô sáng màu vàng chỉ nước đi tốt nhất do AI tính toán gợi ý. | I20: Nút Gợi ý (Hint) hiển thị mũi tên vàng chỉ nước cờ tối ưu do thuật toán AI đề xuất. | J20: Pass | K20: Medium
A21: 17 | B21: TC_GAME_017 | C21: Khai cuộc ECCO | D21: Tự động nhận diện thế trận khai cuộc ECCO | E21: Bắt đầu ván mới | F21: 1. Đỏ đi Pháo 2 bình 5 (Pháo Đầu) 2. Đen đi Mã 8 tiến 7 (Bình Phong Mã) 3. Quan sát chip khai cuộc | G21: Nước đi khai cuộc | H21: Chip ECCO cập nhật tên thế trận chuẩn xác: "ECCO-C01: Pháo Đầu đối Bình Phong Mã". | I21: Tự động nhận diện thế trận khai cuộc ECCO (ví dụ ECCO-C01: Pháo Đầu đối Bình Phong Mã). | J21: Pass | K21: Medium
A22: 18 | B22: TC_GAME_018 | C22: Đánh giá AI | D22: Thanh đánh giá thế trận (Heuristic Evaluation Bar) | E22: Ván cờ đang diễn ra | F22: 1. Đi một nước cờ ăn quân Xe đối phương 2. Quan sát thanh Heuristic Bar bên cạnh bàn cờ | G22: Ăn quân Xe (+900 centipawn) | H22: Thanh Heuristic Bar tăng mạnh dải màu Đỏ thể hiện ưu thế vượt trội (+5.0 đến +9.0 điểm). | I22: Thanh Heuristic Evaluation Bar cập nhật dải màu đỏ/đen tương ứng với chênh lệch điểm số quân lực và vị trí. | J22: Pass | K22: Medium

Sheet 07_TC_Online_SignalR
A1: BỘ KIỂM THỬ ĐẤU TRỰC TUYẾN THỜI GIAN THỰC (ONLINE MULTIPLAYER & SIGNALR)
A2: Kiểm tra Sảnh công khai, Phòng riêng mã 8 ký tự, Đồng bộ nước đi Realtime, Đồng hồ rụng kim, Reconnect
A4: STT | B4: Mã Test Case | C4: Phân hệ / Chức năng | D4: Mục tiêu kiểm thử (Scenario) | E4: Điều kiện tiên quyết (Pre-conditions) | F4: Các bước thực hiện (Test Steps) | G4: Dữ liệu kiểm thử (Test Data) | H4: Kết quả mong đợi (Expected Result) | I4: Kết quả thực tế (Actual Result) | J4: Trạng thái | K4: Ưu tiên | L4: Ghi chú / Bug ID
A5: 1 | B5: TC_ONL_001 | C5: Sảnh chờ | D5: Hiển thị danh sách phòng chờ công khai theo 4 Tier Elo | E5: Người dùng ở trang Sảnh trực tuyến (/Game hoặc Online Lobby) | F5: 1. Vào mục Sảnh chờ công khai 2. Kiểm tra danh sách 4 phân hạng | G5: Tier: Nhập môn, Kỳ thủ, Kiện tướng, Đại sư | H5: Hiển thị đúng 4 phân hạng, số lượng phòng đang mở và các trận đấu đang diễn ra. | I5: Sảnh chờ công khai hiển thị đầy đủ 4 phân hạng Tier Elo (Nhập môn, Kỳ thủ, Kiện tướng, Đại sư). | J5: Pass | K5: High
A6: 2 | B6: TC_ONL_002 | C6: Tạo phòng | D6: Tạo phòng chơi riêng tư sinh mã ngẫu nhiên 8 ký tự | E6: Người dùng đã đăng nhập tài khoản | F6: 1. Chọn "Tạo phòng riêng" 2. Thiết lập thời gian (10 phút) 3. Bấm "Tạo phòng" | G6: Phòng Private, Time: 10m | H6: Hệ thống sinh mã phòng ngẫu nhiên gồm 8 ký tự in hoa (ví dụ: Z8J67ZZA), chuyển người tạo vào trạng thái Chờ đối thủ. | I6: Tạo phòng riêng sinh mã ngẫu nhiên 8 ký tự in hoa (ví dụ Z8J67ZZA) và đưa chủ phòng vào trạng thái chờ. | J6: Pass | K6: High
A7: 3 | B7: TC_ONL_003 | C7: Vào phòng | D7: Nhập mã phòng 8 ký tự hợp lệ để tham gia thi đấu | E7: Phòng "Z8J67ZZA" đang mở chờ đối thủ | F7: 1. Người chơi 2 vào tab "Nhập mã phòng" 2. Nhập chính xác "Z8J67ZZA" 3. Bấm "Vào phòng" | G7: Mã: Z8J67ZZA | H7: Người chơi 2 gia nhập phòng thành công, SignalR thông báo cho cả 2 người, chuyển sang màn hình bàn cờ. | I7: Người chơi thứ 2 nhập mã phòng 8 ký tự tham gia thành công, SignalR thông báo và chuyển vào bàn cờ. | J7: Pass | K7: High
A8: 4 | B8: TC_ONL_004 | C8: Vào phòng | D8: Nhập mã phòng không tồn tại hoặc phòng đã kết thúc | E8: Mã phòng "ABCDEFGH" không có trong hệ thống | F8: 1. Nhập mã "ABCDEFGH" 2. Bấm "Vào phòng" | G8: Mã: ABCDEFGH | H8: Báo lỗi: "Không tìm thấy phòng chơi hoặc phòng đã đóng". Không chuyển màn hình. | I8: Nhập mã phòng không tồn tại bị từ chối với thông báo 'Không tìm thấy phòng chơi hoặc phòng đã đóng'. | J8: Pass | K8: High
A9: 5 | B9: TC_ONL_005 | C9: Vào phòng | D9: Cố gắng vào phòng đã đủ 2 người chơi | E9: Phòng đã có đủ Player Red và Player Black | F9: 1. Người thứ 3 nhập mã phòng 2. Bấm "Vào phòng" | G9: Phòng full | H9: Thông báo: "Phòng đã đủ người chơi. Bạn có muốn vào xem với tư cách Khán giả không?" | I9: Phòng đã đủ 2 người chơi tự động hỏi người thứ 3 vào xem với tư cách Khán giả. | J9: Pass | K9: Medium
A10: 6 | B10: TC_ONL_006 | C10: Bắt đầu trận | D10: Phân chia màu quân Đỏ / Đen và khởi tạo bàn cờ | E10: Cả 2 người chơi đã kết nối vào phòng | F10: 1. Hệ thống xác nhận bắt đầu trận 2. Kiểm tra màu quân của 2 máy | G10: Bắt đầu ván Online | H10: Người chơi Đỏ cầm quân Đỏ ở nửa dưới màn hình. Người chơi Đen cầm quân Đen ở nửa dưới màn hình. | I10: Bắt đầu trận Online: Phân định rõ ràng người chơi Đỏ cầm quân Đỏ dưới, người chơi Đen cầm quân Đen dưới. | J10: Pass | K10: High
A11: 7 | B11: TC_ONL_007 | C11: Realtime SignalR | D11: Đồng bộ nước đi thời gian thực qua SignalR Hub | E11: Ván cờ Online đang diễn ra | F11: 1. Người chơi Đỏ đi Pháo 2 bình 5 trên máy A 2. Quan sát màn hình máy B của đối thủ | G11: Nước đi: b3-e3 | H11: Màn hình máy B tự động cập nhật quân Pháo Đỏ nhảy sang e3 trong thời gian < 150ms mà không cần tải lại trang. | I11: Đồng bộ nước đi thời gian thực qua SignalR Hub đạt độ trễ cực thấp (< 150ms) không cần tải lại trang. | J11: Pass | K11: High
A12: 8 | B12: TC_ONL_008 | C12: Bảo mật nước đi | D12: Chặn nước đi không hợp lệ gửi trực tiếp qua SignalR (Anti-cheat) | E12: Kẻ gian cố tình can thiệp mã WebSocket gửi nước đi sai luật | F12: 1. Bắn lệnh move không hợp lệ qua SignalR Hub (ví dụ Tướng nhảy qua sông) 2. Kiểm tra phản hồi server | G12: Nước đi hack: e1-e6 | H12: Backend GameHub chặn lại ngay lập tức, trả về lỗi InvalidMove, không đồng bộ nước đi này cho đối thủ. | I12: Bảo mật Anti-cheat: GameHub chặn ngay lập tức các lệnh WebSocket chứa nước đi sai luật. | J12: Pass | K12: High
A13: 9 | B13: TC_ONL_009 | C13: Đồng hồ đếm ngược | D13: Đồng hồ đếm ngược mỗi bên giảm đúng theo thời gian thực | E13: Ván đấu 10 phút, đến lượt bên Đỏ | F13: 1. Đỏ suy nghĩ trong 10 giây 2. Quan sát đồng hồ bên Đỏ và Đen | G13: Thời gian suy nghĩ: 10s | H13: Đồng hồ bên Đỏ giảm đúng từ 10:00 xuống 09:50. Đồng hồ bên Đen giữ nguyên đóng băng. | I13: Đồng hồ đếm ngược chỉ giảm bên người chơi đang suy nghĩ, bên đối phương giữ nguyên. | J13: Pass | K13: High
A14: 10 | B14: TC_ONL_010 | C14: Xử lý rụng kim | D14: Nút "⚡ XỬ THẮNG RỤNG KIM" xuất hiện khi đối thủ hết giờ | E14: Đối thủ hết thời gian nước đi (quá 3 phút không đi nước cờ) | F14: 1. Đợi đối thủ quá 3 phút 2. Quan sát nút hành động trên màn hình | G14: Timeout: 3 phút | H14: Xuất hiện nút màu vàng cam nổi bật: "⚡ XỬ THẮNG RỤNG KIM" kèm thông báo đối thủ đã hết giờ. | I14: Nút '⚡ XỬ THẮNG RỤNG KIM' xuất hiện màu cam nổi bật khi đối thủ quá 3 phút không đi nước cờ. | J14: Pass | K14: High
A15: 11 | B15: TC_ONL_011 | C15: Xử lý rụng kim | D15: Nhấn nút Xử thắng rụng kim kết thúc ván cờ ngay lập tức | E15: Nút Xử thắng rụng kim đang hiển thị | F15: 1. Người chơi bấm nút "⚡ XỬ THẮNG RỤNG KIM" 2. Quan sát phản hồi server | G15: Click nút timeout claim | H15: Máy chủ ASP.NET xác thực thời gian, phát thông báo kết thúc ván: "Thắng cuộc do đối thủ rụng kim (hết giờ)", cộng điểm Elo cho người bấm. | I15: Bấm nút Xử thắng rụng kim gửi xác thực lên server, kết thúc ván và cộng điểm Elo người thắng. | J15: Pass | K15: High
A16: 12 | B16: TC_ONL_012 | C16: Cầu hòa | D16: Gửi yêu cầu Cầu hòa (Draw Offer) tới đối thủ | E16: Ván cờ đang ở thế giằng co | F16: 1. Bấm nút "Xin hòa" 2. Kiểm tra màn hình đối thủ | G16: Hành động: Xin hòa | H16: Màn hình đối thủ xuất hiện hộp thoại: "Đối thủ gửi lời mời hòa cờ. Bạn có đồng ý không?" kèm 2 nút Đồng ý / Từ chối. | I16: Gửi yêu cầu Cầu hòa xuất hiện hộp thoại mời hòa trên máy đối thủ kèm 2 nút Đồng ý / Từ chối. | J16: Pass | K16: Medium
... A18: 14 | B18: TC_ONL_014 | C18: Cầu hòa | D18: Đối thủ từ chối yêu cầu Cầu hòa | E18: Hộp thoại mời hòa đang mở | F18: 1. Đối thủ bấm nút "Từ chối" 2. Kiểm tra ván cờ | G18: Chọn: Từ chối hòa | H18: Thông báo cho người xin hòa: "Đối thủ từ chối lời mời hòa". Ván cờ tiếp tục bình thường. | I18: Đối thủ từ chối cầu hòa: Thông báo cho người xin hòa và ván cờ tiếp tục bình thường. | J18: Pass | K18: Medium
A19: 15 | B19: TC_ONL_015 | C19: Đầu hàng | D19: Người chơi bấm Xin hàng (Resign) | E19: Ván đấu đang diễn ra | F19: 1. Bấm nút "Xin hàng" 2. Xác nhận hộp thoại "Bạn có chắc chắn muốn đầu hàng?" | G19: Hành động: Đầu hàng | H19: Ván cờ kết thúc ngay lập tức, đối phương được xử Thắng, người xin hàng bị xử Thua, cập nhật Elo tương ứng. | I19: Người chơi bấm Xin hàng (Resign): Hệ thống xử thua ngay lập tức và cập nhật Elo. | J19: Pass | K19: High | L19: BUG_004 (Đã fix ở Chu kỳ 2 - Commit 65ae81d)
A20: 16 | B20: TC_ONL_016 | C20: Tái đấu | D20: Gửi yêu cầu Tái đấu (Rematch) sau khi kết thúc ván | E20: Ván cờ vừa kết thúc, hiển thị modal kết quả | F20: 1. Bấm nút "Tái đấu" 2. Đối thủ chấp nhận tái đấu | G20: Nút Rematch | H20: Bàn cờ tự động reset về ván mới, đổi bên Đỏ/Đen cho 2 người chơi để công bằng. | I20: Tái đấu (Rematch): Bàn cờ reset về ván mới và tự động đổi bên Đỏ/Đen để đảm bảo công bằng. | J20: Pass | K20: Medium | L20: BUG_012 (Đã fix ở Chu kỳ 2 - Commit 65ae81d)
A21: 17 | B21: TC_ONL_017 | C21: Khán giả | D21: Chế độ Khán giả (Spectator) xem ván đấu trực tiếp | E21: Trận đấu giữa Player A và Player B đang diễn ra | F21: 1. Người thứ 3 bấm "Xem trận" 2. Quan sát bàn cờ | G21: Role: Khán giả | H21: Xem được toàn bộ nước đi realtime, không có các nút di chuyển quân cờ, không can thiệp được ván đấu. | I21: Chế độ Khán giả xem được toàn bộ nước đi realtime nhưng không có các nút can thiệp ván đấu. | J21: Pass | K21: Medium
A22: 18 | B22: TC_ONL_018 | C22: Mất kết nối | D22: Người chơi bị rớt mạng Internet đột ngột | E22: Ván cờ đang chơi, người chơi A bị ngắt mạng Wifi | F22: 1. Rút mạng hoặc tắt Wifi trên máy A 2. Kiểm tra màn hình máy B | G22: Ngắt mạng đột ngột | H22: Máy B nhận thông báo: "Đối thủ tạm thời mất kết nối. Đang chờ kết nối lại... (60s)". | I22: Phát hiện mất kết nối đột ngột: Hiển thị thông báo đếm ngược 60 giây chờ kết nối lại. | J22: Pass | K22: High
A23: 19 | B23: TC_ONL_019 | C23: Kết nối lại | D23: Cơ chế Tự động kết nối lại (Reconnect) thành công | E23: Máy A có mạng trở lại trong vòng 30 giây | F23: 1. Bật lại mạng trên máy A 2. Quan sát ứng dụng | G23: Bật lại Wifi | H23: SignalR tự động kết nối lại vào đúng phòng chơi, khôi phục lại nguyên vẹn thế cờ và đồng hồ đếm ngược. | I23: Cơ chế Reconnect tự động khôi phục đúng phòng chơi, thế cờ và đồng hồ khi có mạng trở lại. | J23: Pass | K23: High
A24: 20 | B24: TC_ONL_020 | C24: Bỏ cuộc | D24: Đối thủ ngắt kết nối quá thời gian chờ (Tự động xử thua) | E24: Người chơi A rớt mạng và không quay lại sau 60 giây | F24: 1. Đợi hết 60 giây đếm ngược mất kết nối 2. Kiểm tra kết quả | G24: Timeout disconnect: 60s | H24: Hệ thống tự động xử Người chơi B thắng do đối thủ bỏ cuộc (Abandonment). | I24: Quá 60 giây mất kết nối: Hệ thống tự động xử đối thủ thắng do người chơi bỏ cuộc (Abandonment). | J24: Pass | K24: High

Sheet 08_TC_Puzzle_Cothe
A1: BỘ KIỂM THỬ HỆ THỐNG CỜ THẾ (PUZZLE CHALLENGE & TIMERUSH)
A2: Kiểm tra Thử thách 5 cấp độ, Timerush 3p/5p/Sinh tồn, Tạo đề tùy chỉnh Elo/Mate, Bản đồ vượt ải
A4: STT | B4: Mã Test Case | C4: Phân hệ / Chức năng | D4: Mục tiêu kiểm thử (Scenario) | E4: Điều kiện tiên quyết (Pre-conditions) | F4: Các bước thực hiện (Test Steps) | G4: Dữ liệu kiểm thử (Test Data) | H4: Kết quả mong đợi (Expected Result) | I4: Kết quả thực tế (Actual Result) | J4: Trạng thái | K4: Ưu tiên | L4: Ghi chú / Bug ID
A5: 1 | B5: TC_PUZ_001 | C5: Hub Cờ thế | D5: Hiển thị đầy đủ 4 chế độ chơi trên Hub Cờ Thế | E5: Truy cập vào menu Cờ Thế (/Puzzle) | F5: 1. Mở trang Cờ Thế 2. Kiểm tra 4 chế độ | G5: Hub Cờ Thế | H5: Hiển thị chuẩn xác 4 thẻ: 1. Thử thách cấp độ, 2. Giải đề tính giờ (Timerush), 3. Tạo đề tùy chỉnh, 4. Lịch sử giải đề. | I5: Hub Cờ Thế hiển thị đầy đủ 4 thẻ chế độ: Thử thách cấp độ, Timerush, Tạo đề tùy chỉnh, Lịch sử giải đề. | J5: Pass | K5: High
A6: 2 | B6: TC_PUZ_002 | C6: Thử thách | D6: Xem danh sách bài cờ thế phân theo 5 cấp độ | E6: Chọn chế độ "Thử thách" | F6: 1. Vào danh sách cấp độ 2. Kiểm tra Cấp 1 đến Cấp 5 | G6: Cấp 1 -> Cấp 5 | H6: Hiển thị danh sách bài tập kèm số sao đạt được, quy tắc yêu cầu (ví dụ: Chiếu bí trong 2 nước). | I6: Danh sách bài cờ thế phân theo 5 cấp độ khó từ Cấp 1 đến Cấp 5 kèm số sao đạt được. | J6: Pass | K6: High
A7: 3 | B7: TC_PUZ_003 | C7: Thử thách | D7: Mở một bài cờ thế cụ thể để giải | E7: Chọn bài cờ "Khởi Mã Phá Trận" | F7: 1. Bấm vào bài cờ 2. Quan sát bàn cờ | G7: Bài cờ #basic:23 | H7: Bàn cờ tải đúng thế cờ tàn, hiển thị tiêu đề, số nước quy định và lượt đi của bên Đỏ. | I7: Mở bài cờ thế tải đúng thế cờ tàn, tiêu đề, số nước quy định và lượt đi của bên Đỏ. | J7: Pass | K7: High
A8: 4 | B8: TC_PUZ_004 | C8: Thử thách | D8: Người chơi đi nước cờ ĐÚNG theo đáp án thế cờ | E8: Đang trong bài cờ thế | F8: 1. Đi nước cờ đúng chiến thuật đầu tiên 2. Quan sát phản hồi của Máy | G8: Nước đi chính xác | H8: Hệ thống xác nhận nước đi đúng, Máy AI tự động đi nước cờ chống đỡ theo kịch bản thế cờ. | I8: Đi nước cờ ĐÚNG theo đáp án: Hệ thống xác nhận và Máy AI đi nước cờ chống đỡ theo kịch bản. | J8: Pass | K8: High
A9: 5 | B9: TC_PUZ_005 | C9: Thử thách | D9: Hoàn thành bài cờ thế và nhận đánh giá 3 sao | E9: Đến nước đi chiếu bí cuối cùng | F9: 1. Đi nước cờ sát cục cuối cùng 2. Kiểm tra popup kết quả | G9: Hoàn thành bài cờ | H9: Hiển thị bảng vinh danh "Thành công!", đạt 3 sao ⭐⭐⭐, cộng điểm tích lũy và mở khóa bài tiếp theo. | I9: Hoàn thành bài cờ: Hiển thị popup vinh danh đạt 3 sao ⭐⭐⭐, cộng điểm và mở khóa bài tiếp theo. | J9: Pass | K9: High
A10: 6 | B10: TC_PUZ_006 | C10: Thử thách | D10: Người chơi đi nước cờ SAI so với đáp án | E10: Đang trong bài cờ thế | F10: 1. Cố ý đi nước cờ sai không tối ưu 2. Quan sát thông báo | G10: Nước đi sai | H10: Hiển thị thông báo màu đỏ: "Nước đi chưa chính xác. Hãy suy nghĩ thêm!", tự động hoàn tác nước cờ vừa đi. | I10: Đi nước cờ SAI: Báo lỗi màu đỏ và tự động hoàn tác nước cờ vừa đi về vị trí cũ. | J10: Pass | K10: High
A11: 7 | B11: TC_PUZ_007 | C11: Timerush | D11: Chế độ Giải đề tính giờ - Chọn Siêu tốc 3 phút | E11: Ở màn hình Giải đề tính thời gian | F11: 1. Chọn thẻ "Siêu tốc 3 phút" 2. Bấm "Bắt đầu chạy đua" | G11: Chế độ 3 phút | H11: Bắt đầu đếm ngược từ 03:00, bài cờ đầu tiên xuất hiện ngay lập tức. | I11: Chế độ Siêu tốc 3 phút: Đồng hồ đếm ngược từ 03:00 và xuất hiện bài cờ đầu tiên ngay lập tức. | J11: Pass | K11: High
A12: 8 | B12: TC_PUZ_008 | C12: Timerush | D12: Giải liên tục các bài cờ trong chế độ 3 phút | E12: Đang trong lượt chạy đua 3 phút | F12: 1. Giải đúng bài 1 -> Chuyển ngay bài 2 2. Giải tiếp các bài tiếp theo | G12: Giải liên tiếp | H12: Điểm số (Score) tăng lên sau mỗi bài giải đúng, đồng hồ tiếp tục đếm ngược không dừng. | I12: Giải liên tục các bài trong Timerush: Điểm số tăng dần sau mỗi bài giải đúng, đồng hồ không dừng. | J12: Pass | K12: High
A13: 9 | B13: TC_PUZ_009 | C13: Timerush | D13: Kết thúc thời gian 3 phút và vinh danh kết quả | E13: Đồng hồ đếm ngược về 00:00 | F13: 1. Để đồng hồ chạy hết 3 phút 2. Kiểm tra màn hình tổng kết | G13: Hết giờ (00:00) | H13: Dừng lượt chơi ngay lập tức, hiển thị tổng số bài giải đúng, kỷ lục cá nhân (High Score) và điểm thưởng. | I13: Hết giờ 3 phút: Dừng lượt chơi, hiển thị tổng số bài giải đúng, kỷ lục High Score và điểm thưởng. | J13: Pass | K13: High
A14: 10 | B14: TC_PUZ_010 | C14: Timerush | D14: Chế độ Sinh tồn (Survival) - Giới hạn 3 mạng | E14: Chọn chế độ "Sinh tồn" | F14: 1. Bắt đầu chơi 2. Đi sai lần 1 -> Mất 1 tim 3. Đi sai lần 2 -> Mất 2 tim 4. Đi sai lần 3 -> Hết tim | G14: Sai 3 lần | H14: Sau 3 lần đi sai, lượt chơi kết thúc ngay lập tức dù chưa hết thời gian. Hiển thị số bài đã giải thành công. | I14: Chế độ Sinh tồn (Survival): Giới hạn 3 mạng, đi sai 3 lần kết thúc lượt chơi dù chưa hết thời gian. | J14: Pass | K14: High
A15: 11 | B15: TC_PUZ_011 | C15: Tùy chỉnh | D15: Tạo đề tùy chỉnh - Lọc theo dải điểm Elo | E15: Mở trang Tạo đề bài tùy chỉnh | F15: 1. Kéo thanh trượt Elo chọn mức "Trung cấp (1400)" 2. Bấm "Tìm kiếm đề bài" | G15: Elo: 1400 | H15: Danh sách trả về các bài cờ thế có độ khó tương đương Elo 1400. | I15: Tạo đề tùy chỉnh lọc theo dải điểm Elo (mức 1400) trả về danh sách bài có độ khó tương đương. | J15: Pass | K15: Medium
A16: 12 | B16: TC_PUZ_012 | C16: Tùy chỉnh | D16: Tạo đề tùy chỉnh - Lọc theo Loại thế cờ | E16: Trang Tạo đề tùy chỉnh | F16: 1. Chọn radio button "Tàn cuộc (<= 6 quân)" 2. Bấm tìm kiếm | G16: Loại: Tàn cuộc | H16: Tất cả bài cờ hiển thị đều là cờ tàn với tổng số quân cờ trên bàn <= 6 quân. | I16: Tạo đề tùy chỉnh lọc theo loại Tàn cuộc (<= 6 quân) hiển thị chính xác các bài cờ thế tàn cục. | J16: Pass | K16: Medium
... A20: 16 | B20: TC_PUZ_016 | C20: Bản đồ vượt ải | D20: Nhận thưởng Rương Bạc và Rương Vàng khi đạt mốc ải | E20: Người chơi vượt qua Ải 4 | F20: 1. Hoàn thành Ải 4 2. Kiểm tra Rương Bạc trên bản đồ 3. Bấm vào rương nhận thưởng | G20: Mốc ải 4 | H20: Rương Bạc mở khóa, hiển thị hiệu ứng nhận thưởng +3 Tim và +2 Gợi ý. | I20: Mốc ải 4: Mở khóa Rương Bạc nhận thưởng +3 Tim và +2 Gợi ý thành công. | J20: Pass | K20: Medium

Sheet 09_TC_Course_Master
A1: BỘ KIỂM THỬ HỌC VIỆN & KỲ PHỔ DANH THỦ (COURSE ACADEMY & MASTER GAMES)
A2: Kiểm tra Khóa học lý thuyết, Quiz trắc nghiệm, Lưu tiến độ API, Chứng chỉ, Trình phát ván cờ danh thủ
A4: STT | B4: Mã Test Case | C4: Phân hệ / Chức năng | D4: Mục tiêu kiểm thử (Scenario) | E4: Điều kiện tiên quyết (Pre-conditions) | F4: Các bước thực hiện (Test Steps) | G4: Dữ liệu kiểm thử (Test Data) | H4: Kết quả mong đợi (Expected Result) | I4: Kết quả thực tế (Actual Result) | J4: Trạng thái | K4: Ưu tiên | L4: Ghi chú / Bug ID
A5: 1 | B5: TC_COU_001 | C5: Khóa học | D5: Hiển thị danh mục các khóa học tại Học Viện Cờ | E5: Truy cập vào menu Khóa học (/Course) | F5: 1. Mở trang Khóa học 2. Kiểm tra các module | G5: Module: Nhập môn, Tàn cuộc, Sát pháp, Bố cục | H5: Hiển thị đầy đủ 4 module khóa học kèm ảnh bìa, số lượng bài học và mô tả tóm tắt. | I5: Học viện cờ hiển thị đầy đủ 4 module khóa học: Nhập môn, Tàn cuộc, Sát pháp, Bố cục. | J5: Pass | K5: High
A6: 2 | B6: TC_COU_002 | C6: Khóa học | D6: Xem chi tiết danh sách bài giảng trong một khóa học | E6: Chọn khóa học "Nhập Môn Cờ Tướng" | F6: 1. Bấm vào khóa học Nhập môn 2. Kiểm tra các bài giảng | G6: Khóa học Nhập môn | H6: Hiển thị danh sách các bài học: Luật 7 quân cờ, Cản chân mã, Cản mắt tượng, Thế trận pháo đầu,... | I6: Xem chi tiết khóa học hiển thị danh sách bài giảng bài bản theo thứ tự. | J6: Pass | K6: High
A7: 3 | B7: TC_COU_003 | C7: Khóa học | D7: Xem nội dung bài giảng lý thuyết kèm bàn cờ tương tác | E7: Mở bài học "Quy tắc di chuyển quân Mã" | F7: 1. Đọc nội dung lý thuyết 2. Quan sát bàn cờ minh họa bên cạnh | G7: Bài học quân Mã | H7: Bàn cờ minh họa hiển thị đúng vị trí quân Mã và các mũi tên chỉ hướng đi, cản chân mã. | I7: Nội dung bài giảng kèm bàn cờ minh họa tương tác hiển thị đúng vị trí quân và mũi tên chỉ dẫn. | J7: Pass | K7: High
A8: 4 | B8: TC_COU_004 | C8: Khóa học | D8: Thao tác đi thử trên bàn cờ minh họa bài học | E8: Đang ở bài học tương tác | F8: 1. Chạm vào quân cờ trên bàn cờ bài học 2. Thử đi nước cờ theo hướng dẫn | G8: Thao tác bàn cờ bài học | H8: Bàn cờ cho phép đi thử nghiệm nước cờ, có thông báo nhận xét nước đi đúng/sai. | I8: Bàn cờ bài học cho phép thao tác đi thử nghiệm và phản hồi đúng/sai trực quan. | J8: Pass | K8: Medium
A9: 5 | B9: TC_COU_005 | C9: Trắc nghiệm Quiz | D9: Làm bài kiểm tra trắc nghiệm cuối bài học | E9: Đọc xong phần lý thuyết bài học | F9: 1. Bấm nút "Làm bài tập Quiz" 2. Đọc câu hỏi trắc nghiệm | G9: Câu hỏi Quiz | H9: Hiển thị câu hỏi kèm bàn cờ tình huống và 4 phương án lựa chọn A, B, C, D. | I9: Bài kiểm tra Quiz trắc nghiệm hiển thị câu hỏi tình huống kèm 4 phương án A, B, C, D. | J9: Pass | K9: High
A10: 6 | B10: TC_COU_006 | C10: Trắc nghiệm Quiz | D10: Chọn phương án trả lời ĐÚNG trong bài Quiz | E10: Đang ở câu hỏi trắc nghiệm | F10: 1. Chọn đáp án chính xác 2. Bấm "Gửi câu trả lời" | G10: Đáp án đúng | H10: Hiển thị tích xanh ✔, có âm thanh chúc mừng, cộng điểm tiến độ bài học. | I10: Chọn đáp án ĐÚNG trong Quiz hiển thị tích xanh ✔, phát âm thanh chúc mừng và cộng điểm tiến độ. | J10: Pass | K10: High | L10: BUG_013 (Đã fix ở Chu kỳ 2 - Commit 65ae81d)
A11: 7 | B11: TC_COU_007 | C11: Trắc nghiệm Quiz | D11: Chọn phương án trả lời SAI trong bài Quiz | E11: Đang ở câu hỏi trắc nghiệm | F11: 1. Chọn một đáp án sai 2. Bấm "Gửi câu trả lời" | G11: Đáp án sai | H11: Hiển thị dấu X đỏ ✖, hiển thị giải thích chi tiết vì sao đáp án đó chưa chính xác và cho phép thử lại. | I11: Chọn đáp án SAI trong Quiz hiển thị dấu X đỏ ✖ kèm lời giải thích chi tiết vì sao sai. | J11: Pass | K11: Medium
A12: 8 | B12: TC_COU_008 | C12: Lưu tiến độ | D12: Lưu tiến độ học tập tự động lên máy chủ qua API | E12: Người dùng hoàn thành 1 bài học | F12: 1. Hoàn thành bài học và quiz 2. Kiểm tra lưu trữ CSDL | G12: API /api/courses/progress | H12: Máy chủ lưu trạng thái isCompleted = true, điểm quizScore = 100%, tỷ lệ % hoàn thành khóa học tăng lên. | I12: Lưu tiến độ qua API /api/courses/progress: Ghi nhận isCompleted = true và cập nhật % khóa học. | J12: Pass | K12: High | L12: BUG_006 (Đã fix ở Chu kỳ 2 - Commit 65ae81d)
A13: 9 | B13: TC_COU_009 | C13: Chứng chỉ | D13: Cấp Chứng chỉ hoàn thành khóa học (Certificate) | E13: Người dùng hoàn thành 100% tất cả bài học trong khóa | F13: 1. Hoàn thành bài học cuối cùng 2. Bấm "Xem Chứng Chỉ" | G13: Khóa học 100% | H13: Hệ thống hiển thị Chứng chỉ tốt nghiệp trang trọng với tên người học, tên khóa học, ngày cấp và mã chứng nhận. | I13: Hoàn thành 100% khóa học: Cấp Chứng chỉ tốt nghiệp điện tử trang trọng kèm mã xác thực. | J13: Pass | K13: Medium | L13: BUG_005 (Đã fix ở Chu kỳ 2 - Commit 65ae81d)
A14: 10 | B14: TC_MAS_001 | C14: Kỳ phổ danh thủ | D14: Xem danh mục các ván cờ danh thủ kinh điển | E14: Truy cập vào menu Kỳ phổ (/MasterGame) | F14: 1. Mở trang Kỳ phổ 2. Kiểm tra danh sách ván đấu | G14: Danh mục Kỳ phổ | H14: Hiển thị danh sách các ván đấu đỉnh cao của các đại sư (Hứa Ngân Xuyên, Vương Thiên Nhất, Lại Lý Huynh, Hồ Vinh Hoa,...). | I14: Danh mục Kỳ phổ hiển thị các ván đấu kinh điển của đại sư (Hứa Ngân Xuyên, Vương Thiên Nhất,...). | J14: Pass | K14: High
A15: 11 | B15: TC_MAS_002 | C15: Kỳ phổ danh thủ | D15: Tìm kiếm ván cờ theo tên danh thủ | E15: Trang Kỳ phổ danh thủ | F15: 1. Nhập "Vương Thiên Nhất" vào ô tìm kiếm 2. Bấm Tìm kiếm | G15: Từ khóa: Vương Thiên Nhất | H15: Bộ lọc hiển thị chính xác các ván cờ do danh thủ Vương Thiên Nhất thi đấu. | I15: Tìm kiếm kỳ phổ theo tên danh thủ 'Vương Thiên Nhất' lọc chính xác các ván đấu tương ứng. | J15: Pass | K15: Medium
A16: 12 | B16: TC_MAS_003 | C16: Kỳ phổ danh thủ | D16: Lọc ván cờ theo giải đấu và năm thi đấu | E16: Trang Kỳ phổ danh thủ | F16: 1. Chọn giải "Giáp Cấp Liên Tái" 2. Bấm Lọc | G16: Giải đấu: Giáp Cấp Liên Tái | H16: Hiển thị các ván đấu thuộc giải đấu đã chọn. | I16: Lọc kỳ phổ theo giải đấu và năm thi đấu hiển thị danh sách ván đấu chuẩn xác. | J16: Pass | K16: Medium
A17: 13 | B17: TC_MAS_004 | C17: Kỳ phổ danh thủ | D17: Mở chi tiết một ván cờ danh thủ để nghiên cứu | E17: Bấm vào ván cờ "Hứa Ngân Xuyên vs Lữ Khâm (1998)" | F17: 1. Mở ván cờ 2. Quan sát giao diện trình phát | G17: Ván cờ kinh điển | H17: Bàn cờ tải đúng thế cờ ban đầu, hiển thị danh sách toàn bộ nước đi PGN, thông tin hai bên và kết quả trận. | I17: Mở ván cờ danh thủ tải đúng thế cờ ban đầu, danh sách nước đi PGN và thông tin hai bên. | J17: Pass | K17: High
A18: 14 | B18: TC_MAS_005 | C18: Trình phát kỳ phổ | D18: Điều khiển xem ván cờ với nút Nước trước và Nước sau | E18: Đang mở ván cờ danh thủ | F18: 1. Bấm nút "Nước sau" (Next) 3 lần 2. Bấm nút "Nước trước" (Prev) 1 lần | G18: Nút Next / Prev | H18: Quân cờ trên bàn tự động di chuyển tiến/lùi chính xác theo đúng từng nước đi của danh thủ. | I18: Nút Nước trước (Prev) và Nước sau (Next) di chuyển quân cờ tiến/lùi chuẩn xác theo danh thủ. | J18: Pass | K18: High
A19: 15 | B19: TC_MAS_006 | C19: Trình phát kỳ phổ | D19: Điều khiển về Đầu ván (First) và Đến cuối ván (Last) | E19: Đang ở giữa ván cờ | F19: 1. Bấm nút "Về đầu ván" 2. Bấm nút "Đến cuối ván" | G19: Nút First / Last | H19: Về đầu: Bàn cờ trở lại vị trí xuất phát ban đầu. Đến cuối: Bàn cờ nhảy ngay đến thế trận kết thúc ván. | I19: Nút Về đầu (First) và Đến cuối (Last) chuyển ngay về thế cờ ban đầu hoặc thế cờ kết thúc ván. | J19: Pass | K19: Medium
A20: 16 | B20: TC_MAS_007 | C20: Trình phát kỳ phổ | D20: Tính năng Tự động phát ván cờ (Auto-play) | E20: Đang ở đầu ván cờ | F20: 1. Bấm nút "Tự động phát" (Play) 2. Quan sát bàn cờ chạy | G20: Nút Auto-play | H20: Bàn cờ tự động đi từng nước theo chu kỳ 1.5 giây/nước, danh sách nước đi bên phải tự cuộn theo nước hiện tại. | I20: Tự động phát ván cờ (Auto-play) đi từng nước theo chu kỳ 1.5s và tự cuộn danh sách nước đi. | J20: Pass | K20: Medium

Sheet 10_TC_Admin_System
A1: BỘ KIỂM THỬ PHÂN HỆ QUẢN TRỊ VIÊN (ADMINISTRATION & CMS)
A2: Kiểm tra Phân quyền Admin, Quản lý tài khoản, Quản lý bài cờ thế FEN, Quản lý khóa học, AI Benchmark
A4: STT | B4: Mã Test Case | C4: Phân hệ / Chức năng | D4: Mục tiêu kiểm thử (Scenario) | E4: Điều kiện tiên quyết (Pre-conditions) | F4: Các bước thực hiện (Test Steps) | G4: Dữ liệu kiểm thử (Test Data) | H4: Kết quả mong đợi (Expected Result) | I4: Kết quả thực tế (Actual Result) | J4: Trạng thái | K4: Ưu tiên | L4: Ghi chú / Bug ID
A5: 1 | B5: TC_ADM_001 | C5: Đăng nhập Admin | D5: Đăng nhập tài khoản có quyền Quản trị viên (Admin) | E5: Tài khoản có Role = "Admin" trong CSDL | F5: 1. Đăng nhập tài khoản admin 2. Bấm vào menu "Quản trị" (/Admin) | G5: Tài khoản Admin | H5: Truy cập thành công vào Bảng điều khiển quản trị viên, hiển thị đầy đủ các menu quản lý. | I5: Đăng nhập tài khoản quyền Admin truy cập thành công vào Bảng điều khiển quản trị viên /Admin. | J5: Pass | K5: High
A6: 2 | B6: TC_ADM_002 | C6: Phân quyền | D6: Tài khoản thường (Role: User) bị chặn khi truy cập /Admin | E6: Đăng nhập tài khoản thường | F6: 1. Cố tình gõ trực tiếp URL http://localhost:5000/Admin trên thanh địa chỉ 2. Bấm Enter | G6: Tài khoản User | H6: Hệ thống chặn truy cập, chuyển hướng sang trang Từ chối quyền truy cập (Access Denied - 403 Forbidden). | I6: Tài khoản thường (User) cố tình truy cập /Admin bị chặn và trả về 403 Forbidden / Access Denied. | J6: Pass | K6: High | L6: BUG_003 (Đã fix ở Chu kỳ 2 - Commit 65ae81d)
A7: 3 | B7: TC_ADM_003 | C7: Quản lý người dùng | D7: Xem danh sách toàn bộ người dùng trong hệ thống | E7: Admin ở trang /Admin/Users | F7: 1. Mở mục Quản lý người dùng 2. Kiểm tra danh sách bảng | G7: Trang /Admin/Users | H7: Hiển thị danh sách người dùng gồm: ID, Username, Email, Điểm Elo, Ngày tạo, Vai trò (Role), Trạng thái kích hoạt. | I7: Trang /Admin/Users hiển thị danh sách người dùng gồm ID, Username, Email, Elo, Role, IsActive. | J7: Pass | K7: High
